Traceback (most recent call last):
  File "/Users/nce8/opt/miniconda3/lib/python3.10/site-packages/jupyter_cache/executors/utils.py", line 51, in single_nb_execution
    executenb(
  File "/Users/nce8/opt/miniconda3/lib/python3.10/site-packages/nbclient/client.py", line 1204, in execute
    return NotebookClient(nb=nb, resources=resources, km=km, **kwargs).execute()
  File "/Users/nce8/opt/miniconda3/lib/python3.10/site-packages/nbclient/util.py", line 84, in wrapped
    return just_run(coro(*args, **kwargs))
  File "/Users/nce8/opt/miniconda3/lib/python3.10/site-packages/nbclient/util.py", line 62, in just_run
    return loop.run_until_complete(coro)
  File "/Users/nce8/opt/miniconda3/lib/python3.10/asyncio/base_events.py", line 649, in run_until_complete
    return future.result()
  File "/Users/nce8/opt/miniconda3/lib/python3.10/site-packages/nbclient/client.py", line 663, in async_execute
    await self.async_execute_cell(
  File "/Users/nce8/opt/miniconda3/lib/python3.10/site-packages/nbclient/client.py", line 965, in async_execute_cell
    await self._check_raise_for_error(cell, cell_index, exec_reply)
  File "/Users/nce8/opt/miniconda3/lib/python3.10/site-packages/nbclient/client.py", line 862, in _check_raise_for_error
    raise CellExecutionError.from_cell_and_msg(cell, exec_reply_content)
nbclient.exceptions.CellExecutionError: An error occurred while executing the following cell:
------------------
library(dplyr)
country <- rep(c("USA", "China", "Sudan"), 3)
year <- c(1994, 1994, 1994, 1995, 1995, 1995, 1996, 1996, 1996)
gdp_pc <- round(runif(9, 1000, 20000))

countries <- data.frame(country, year, gdp_pc)
countries
------------------

Error in library(dplyr): there is no package called ‘dplyr’
Traceback:

1. library(dplyr)
ERROR: Error in library(dplyr): there is no package called ‘dplyr’


