Traceback (most recent call last):
  File "/Users/nce8/opt/miniconda3/lib/python3.10/site-packages/jupyter_cache/executors/utils.py", line 51, in single_nb_execution
    executenb(
  File "/Users/nce8/opt/miniconda3/lib/python3.10/site-packages/nbclient/client.py", line 1204, in execute
    return NotebookClient(nb=nb, resources=resources, km=km, **kwargs).execute()
  File "/Users/nce8/opt/miniconda3/lib/python3.10/site-packages/nbclient/util.py", line 84, in wrapped
    return just_run(coro(*args, **kwargs))
  File "/Users/nce8/opt/miniconda3/lib/python3.10/site-packages/nbclient/util.py", line 62, in just_run
    return loop.run_until_complete(coro)
  File "/Users/nce8/opt/miniconda3/lib/python3.10/asyncio/base_events.py", line 649, in run_until_complete
    return future.result()
  File "/Users/nce8/opt/miniconda3/lib/python3.10/site-packages/nbclient/client.py", line 663, in async_execute
    await self.async_execute_cell(
  File "/Users/nce8/opt/miniconda3/lib/python3.10/site-packages/nbclient/client.py", line 965, in async_execute_cell
    await self._check_raise_for_error(cell, cell_index, exec_reply)
  File "/Users/nce8/opt/miniconda3/lib/python3.10/site-packages/nbclient/client.py", line 862, in _check_raise_for_error
    raise CellExecutionError.from_cell_and_msg(cell, exec_reply_content)
nbclient.exceptions.CellExecutionError: An error occurred while executing the following cell:
------------------
import altair as alt
import altair_saver
import pandas as pd
data = pd.read_csv("neg_anscombes.csv")
for i in range(1, 5):
    c = (alt.Chart(data).mark_point()
    .encode(
        x=alt.X(f"x_{i}", scale=alt.Scale(zero=False)),
        y=alt.Y(f"y_{i}", scale=alt.Scale(zero=False))
    ))
    fit = c.transform_regression(
        f"y_{i}", f"x_{i}"
    ).mark_line()
    o = fit + c
    o.show()
    altair_saver.save(o, f"../images/anscombes_{i}.png")
------------------

[0;31m---------------------------------------------------------------------------[0m
[0;31mValueError[0m                                Traceback (most recent call last)
Cell [0;32mIn[1], line 16[0m
[1;32m     14[0m o [38;5;241m=[39m fit [38;5;241m+[39m c
[1;32m     15[0m o[38;5;241m.[39mshow()
[0;32m---> 16[0m [43maltair_saver[49m[38;5;241;43m.[39;49m[43msave[49m[43m([49m[43mo[49m[43m,[49m[43m [49m[38;5;124;43mf[39;49m[38;5;124;43m"[39;49m[38;5;124;43m../images/anscombes_[39;49m[38;5;132;43;01m{[39;49;00m[43mi[49m[38;5;132;43;01m}[39;49;00m[38;5;124;43m.png[39;49m[38;5;124;43m"[39;49m[43m)[49m

File [0;32m~/opt/miniconda3/lib/python3.10/site-packages/altair_saver/_core.py:62[0m, in [0;36msave[0;34m(chart, fp, fmt, mode, method, **kwargs)[0m
[1;32m     41[0m [38;5;250m[39m[38;5;124;03m"""Save an Altair, Vega, or Vega-Lite chart[39;00m
[1;32m     42[0m 
[1;32m     43[0m [38;5;124;03mParameters[39;00m
[0;32m   (...)[0m
[1;32m     59[0m [38;5;124;03m    Additional keyword arguments are passed to Saver initialization.[39;00m
[1;32m     60[0m [38;5;124;03m"""[39;00m
[1;32m     61[0m [38;5;28;01mif[39;00m method [38;5;129;01mis[39;00m [38;5;28;01mNone[39;00m:
[0;32m---> 62[0m     Saver [38;5;241m=[39m [43m_get_saver_for_format[49m[43m([49m[43mfmt[49m[38;5;241;43m=[39;49m[43mfmt[49m[43m,[49m[43m [49m[43mfp[49m[38;5;241;43m=[39;49m[43mfp[49m[43m)[49m
[1;32m     63[0m [38;5;28;01melif[39;00m [38;5;28misinstance[39m(method, [38;5;28mtype[39m):
[1;32m     64[0m     Saver [38;5;241m=[39m method

File [0;32m~/opt/miniconda3/lib/python3.10/site-packages/altair_saver/_core.py:30[0m, in [0;36m_get_saver_for_format[0;34m(fmt, fp)[0m
[1;32m     28[0m     [38;5;28;01mif[39;00m fmt [38;5;129;01min[39;00m s[38;5;241m.[39mvalid_formats [38;5;129;01mand[39;00m s[38;5;241m.[39menabled():
[1;32m     29[0m         [38;5;28;01mreturn[39;00m s
[0;32m---> 30[0m [38;5;28;01mraise[39;00m [38;5;167;01mValueError[39;00m([38;5;124mf[39m[38;5;124m"[39m[38;5;124mUnsupported format: [39m[38;5;132;01m{[39;00mfmt[38;5;132;01m!r}[39;00m[38;5;124m"[39m)

[0;31mValueError[0m: Unsupported format: 'png'
ValueError: Unsupported format: 'png'

